<?xml version="1.0" ?>
<sdf version="1.9">
  <world name="landmarks_world">
    <physics name="1ms" type="ode">
      <max_step_size>0.01</max_step_size>
      <real_time_factor>1.0</real_time_factor>
    </physics>

    <plugin filename="gz-sim-physics-system" name="gz::sim::systems::Physics"></plugin>
    <plugin filename="gz-sim-user-commands-system" name="gz::sim::systems::UserCommands"></plugin>
    <plugin filename="gz-sim-scene-broadcaster-system" name="gz::sim::systems::SceneBroadcaster"></plugin>

    <light type="directional" name="sun">
      <cast_shadows>true</cast_shadows>
      <pose>0 0 10 0 0 0</pose>
      <diffuse>0.8 0.8 0.8 1</diffuse>
      <direction>-0.5 0.1 -0.9</direction>
    </light>

    <model name="ground_plane">
      <static>true</static>
      <link name="link">
        <collision name="collision">
          <geometry><plane><normal>0 0 1</normal><size>100 100</size></plane></geometry>
        </collision>
        <visual name="visual">
          <geometry><plane><normal>0 0 1</normal><size>100 100</size></plane></geometry>
          <material><ambient>0.5 0.5 0.5 1</ambient><diffuse>0.5 0.5 0.5 1</diffuse></material>
        </visual>
      </link>
    </model>

    <!-- Six landmarks: id, position (x y z), colour. MUST match LANDMARK_CONFIGS
         in ekf_slam/landmark_sensor_node.py -->
    <model name="landmark_0_red">
      <static>true</static>
      <pose>3 3 0.3 0 0 0</pose>
      <link name="link">
        <collision name="collision"><geometry><sphere><radius>0.3</radius></sphere></geometry></collision>
        <visual name="visual">
          <geometry><sphere><radius>0.3</radius></sphere></geometry>
          <material><ambient>1 0 0 1</ambient><diffuse>1 0 0 1</diffuse></material>
        </visual>
      </link>
    </model>
    <model name="landmark_1_green">
      <static>true</static>
      <pose>3 -3 0.3 0 0 0</pose>
      <link name="link">
        <collision name="collision"><geometry><sphere><radius>0.3</radius></sphere></geometry></collision>
        <visual name="visual">
          <geometry><sphere><radius>0.3</radius></sphere></geometry>
          <material><ambient>0 1 0 1</ambient><diffuse>0 1 0 1</diffuse></material>
        </visual>
      </link>
    </model>
    <model name="landmark_2_blue">
      <static>true</static>
      <pose>-3 3 0.3 0 0 0</pose>
      <link name="link">
        <collision name="collision"><geometry><sphere><radius>0.3</radius></sphere></geometry></collision>
        <visual name="visual">
          <geometry><sphere><radius>0.3</radius></sphere></geometry>
          <material><ambient>0 0 1 1</ambient><diffuse>0 0 1 1</diffuse></material>
        </visual>
      </link>
    </model>
    <model name="landmark_3_yellow">
      <static>true</static>
      <pose>-3 -3 0.3 0 0 0</pose>
      <link name="link">
        <collision name="collision"><geometry><sphere><radius>0.3</radius></sphere></geometry></collision>
        <visual name="visual">
          <geometry><sphere><radius>0.3</radius></sphere></geometry>
          <material><ambient>1 1 0 1</ambient><diffuse>1 1 0 1</diffuse></material>
        </visual>
      </link>
    </model>
    <model name="landmark_4_magenta">
      <static>true</static>
      <pose>0 4 0.3 0 0 0</pose>
      <link name="link">
        <collision name="collision"><geometry><sphere><radius>0.3</radius></sphere></geometry></collision>
        <visual name="visual">
          <geometry><sphere><radius>0.3</radius></sphere></geometry>
          <material><ambient>1 0 1 1</ambient><diffuse>1 0 1 1</diffuse></material>
        </visual>
      </link>
    </model>
    <model name="landmark_5_cyan">
      <static>true</static>
      <pose>4 0 0.3 0 0 0</pose>
      <link name="link">
        <collision name="collision"><geometry><sphere><radius>0.3</radius></sphere></geometry></collision>
        <visual name="visual">
          <geometry><sphere><radius>0.3</radius></sphere></geometry>
          <material><ambient>0 1 1 1</ambient><diffuse>0 1 1 1</diffuse></material>
        </visual>
      </link>
    </model>

    <!-- Simple differential-drive robot -->
    <model name="ekf_robot">
      <pose>0 0 0.1 0 0 0</pose>
      <link name="chassis">
        <inertial>
          <mass>5.0</mass>
          <inertia><ixx>0.0542</ixx><iyy>0.0833</iyy><izz>0.1042</izz>
                    <ixy>0</ixy><ixz>0</ixz><iyz>0</iyz></inertia>
        </inertial>
        <collision name="collision">
          <geometry><box><size>0.4 0.3 0.2</size></box></geometry>
        </collision>
        <visual name="visual">
          <geometry><box><size>0.4 0.3 0.2</size></box></geometry>
          <material><ambient>0.2 0.2 0.8 1</ambient><diffuse>0.2 0.2 0.8 1</diffuse></material>
        </visual>
      </link>

      <link name="left_wheel">
        <pose>0 0.2 0 -1.5707963 0 0</pose>
        <inertial>
          <mass>0.5</mass>
          <inertia><ixx>0.00135</ixx><iyy>0.00135</iyy><izz>0.0025</izz>
                    <ixy>0</ixy><ixz>0</ixz><iyz>0</iyz></inertia>
        </inertial>
        <collision name="collision">
          <geometry><cylinder><radius>0.1</radius><length>0.05</length></cylinder></geometry>
          <surface><friction><ode><mu>1.0</mu><mu2>1.0</mu2></ode></friction></surface>
        </collision>
        <visual name="visual">
          <geometry><cylinder><radius>0.1</radius><length>0.05</length></cylinder></geometry>
          <material><ambient>0.1 0.1 0.1 1</ambient></material>
        </visual>
      </link>

      <link name="right_wheel">
        <pose>0 -0.2 0 -1.5707963 0 0</pose>
        <inertial>
          <mass>0.5</mass>
          <inertia><ixx>0.00135</ixx><iyy>0.00135</iyy><izz>0.0025</izz>
                    <ixy>0</ixy><ixz>0</ixz><iyz>0</iyz></inertia>
        </inertial>
        <collision name="collision">
          <geometry><cylinder><radius>0.1</radius><length>0.05</length></cylinder></geometry>
          <surface><friction><ode><mu>1.0</mu><mu2>1.0</mu2></ode></friction></surface>
        </collision>
        <visual name="visual">
          <geometry><cylinder><radius>0.1</radius><length>0.05</length></cylinder></geometry>
          <material><ambient>0.1 0.1 0.1 1</ambient></material>
        </visual>
      </link>

      <link name="caster">
        <pose>-0.15 0 -0.05 0 0 0</pose>
        <inertial><mass>0.1</mass>
          <inertia><ixx>0.0001</ixx><iyy>0.0001</iyy><izz>0.0001</izz>
                    <ixy>0</ixy><ixz>0</ixz><iyz>0</iyz></inertia>
        </inertial>
        <collision name="collision">
          <geometry><sphere><radius>0.05</radius></sphere></geometry>
          <surface><friction><ode><mu>0.01</mu><mu2>0.01</mu2></ode></friction></surface>
        </collision>
        <visual name="visual">
          <geometry><sphere><radius>0.05</radius></sphere></geometry>
        </visual>
      </link>

      <joint name="left_wheel_joint" type="revolute">
        <parent>chassis</parent><child>left_wheel</child>
        <axis><xyz>0 0 1</xyz><limit><lower>-1e9</lower><upper>1e9</upper></limit></axis>
      </joint>
      <joint name="right_wheel_joint" type="revolute">
        <parent>chassis</parent><child>right_wheel</child>
        <axis><xyz>0 0 1</xyz><limit><lower>-1e9</lower><upper>1e9</upper></limit></axis>
      </joint>
      <joint name="caster_joint" type="fixed">
        <parent>chassis</parent><child>caster</child>
      </joint>

      <plugin filename="gz-sim-diff-drive-system" name="gz::sim::systems::DiffDrive">
        <left_joint>left_wheel_joint</left_joint>
        <right_joint>right_wheel_joint</right_joint>
        <wheel_separation>0.4</wheel_separation>
        <wheel_radius>0.1</wheel_radius>
        <odom_publish_frequency>10</odom_publish_frequency>
        <topic>cmd_vel</topic>
        <odom_topic>odom</odom_topic>
        <frame_id>world</frame_id>
        <child_frame_id>base_link_gt</child_frame_id>
      </plugin>
    </model>
  </world>
</sdf>
